<b>Исключения в конструкторах и деструкторах</b>

Исключения в конструкторах
Помимо ситуации, когда уже невозможно создать объект с помощью операции *new* и генерируется исключение типа *bad_alloc*, случается так, что исключение происходит при создании объекта, то есть внутри конструктора объекта. Так как в C++ конструктор не возвращает никакого значения, исключения представляются единственным способом обработки ошибок при создании объекта.

Представим, что у нас есть класс *Divider*, который имеет функцию *divide*, она принимает аргумент — число, на которое необходимо разделить.

При запуске нашей программы, мы увидим следующий вывод:

<code>Exception caught: Divider can not be 0!</code>

Как мы можем видеть, при создании объекта мы сгенерировали исключение и перехватили его, при этом деструктор не был вызван, так как объект не был создан.
